<?xml version="1.0"?>

<robot xmlns:xacro="http://www.ros.org/wiki/xacro"
       name="furbo">

       <link name="base_link">
              <visual>
                     <origin xyz="0 0 0" rpy="0 0 0"/>

                     <geometry>
                            <box size="0.35 0.25 0.10"/>
                     </geometry>

                     <material name="blue">
                            <color rgba="0.2 0.4 0.9 1"/>
                     </material>
              </visual>

              <collision>
                     <origin xyz="0 0 0" rpy="0 0 0"/>

                     <geometry>
                            <box size="0.35 0.25 0.10"/>
                     </geometry>
              </collision>

              <inertial>
                     <origin xyz="0 0 0" rpy="0 0 0"/>

                     <mass value="5.0"/>

                     <inertia ixx="0.0302"
                     ixy="0.0"
                     ixz="0.0"
                     iyy="0.0552"
                     iyz="0.0"
                     izz="0.0771"/>
              </inertial>
       </link>

       <link name="left_wheel">
              <visual>
                  <origin xyz="0 0 0" rpy="1.5708 0 0"/>
          
                  <geometry>
                      <cylinder radius="0.05" length="0.03"/>
                  </geometry>
          
                  <material name="black">
                      <color rgba="0.1 0.1 0.1 1"/>
                  </material>
              </visual>
          
              <collision>
                  <origin xyz="0 0 0" rpy="1.5708 0 0"/>
          
                  <geometry>
                      <cylinder radius="0.05" length="0.03"/>
                  </geometry>
              </collision>
          
              <inertial>
                  <mass value="0.3"/>
          
                  <origin xyz="0 0 0"/>
          
                  <inertia
                      ixx="0.0005"
                      ixy="0"
                      ixz="0"
                      iyy="0.0005"
                      iyz="0"
                      izz="0.0005"/>
              </inertial>
          </link>

          <joint name="left_wheel_joint" type="continuous">

              <parent link="base_link"/>
          
              <child link="left_wheel"/>
          
              <origin xyz="0 0.14 -0.05" rpy="0 0 0"/>
          
              <axis xyz="0 1 0"/>
          
          </joint>

          

</robot>